<?xml version="1.0" ?>
<!-- =================================================================================== -->
<!-- |    This document was autogenerated by xacro from blue_dexnet.urdf.xacro         | -->
<!-- |    EDITING THIS FILE BY HAND IS NOT RECOMMENDED                                 | -->
<!-- =================================================================================== -->
<robot name="blue_descriptions_dexnet" xmlns:xacro="http://ros.org/wiki/xacro">
  <!-- Right arm support only -->
  <link name="right_base_link">
    <inertial>
      <origin rpy="0 0 0" xyz="0.0560024374186662 0.000189445541681321 0.0201835602327798"/>
      <mass value="0.284612172465311"/>
      <inertia ixx="0.000716950374478633" ixy="-4.58477843167981E-06" ixz="4.20772050305934E-06" iyy="0.00197711566495113" iyz="9.13561852910017E-07" izz="0.00239705630031167"/>
    </inertial>
    <visual>
      <origin rpy="0 0 0" xyz="0 0 0"/>
      <geometry>
        <mesh filename="package://blue_descriptions/meshes/arm_base_link.STL"/>
      </geometry>
      <material name="">
        <color rgba="0.792156862745098 0.819607843137255 0.933333333333333 1"/>
      </material>
    </visual>
    <collision>
      <origin rpy="0 0 0" xyz="0 0 0"/>
      <geometry>
        <mesh filename="package://blue_descriptions/meshes/arm_base_link.STL"/>
      </geometry>
    </collision>
  </link>
  <joint name="right_base_roll_joint" type="revolute">
    <origin rpy="3.1416 -2.2011E-29 0.0" xyz="0 0 0.087371"/>
    <parent link="right_base_link"/>
    <child link="right_shoulder_roll_link"/>
    <axis xyz="0 0 1"/>
    <limit effort="800" lower="-3.3999" upper="2.3412" velocity="50"/>
  </joint>
  <link name="camera_base_link">
    <inertial>
      <origin rpy="0 0 0" xyz="0.013428 0.042537 0.33147"/>
      <mass value="0.72241"/>
      <inertia ixx="0.042295" ixy="0.000279" ixz="0.001393" iyy="0.039578" iyz="-0.0036206" izz="0.0036069"/>
    </inertial>
    <visual>
      <origin rpy="0 0 0" xyz="0 0 0"/>
      <geometry>
        <mesh filename="package://blue_dexnet/meshes/camera_base_link.STL"/>
      </geometry>
      <material name="">
        <color rgba="0.79216 0.81961 0.93333 1"/>
      </material>
    </visual>
    <collision>
      <origin rpy="0 0 0" xyz="0 0 0"/>
      <geometry>
        <mesh filename="package://blue_dexnet/meshes/camera_base_link.STL"/>
      </geometry>
    </collision>
  </link>
  <joint name="camera_base_joint" type="fixed">
    <origin rpy="-3.5679E-18 2.6645E-15 -3.1416" xyz="0.20002 0.097409 -0.0254"/>
    <parent link="right_base_link"/>
    <child link="camera_base_link"/>
    <axis xyz="0 0 0"/>
  </joint>
  <link name="camera_link">
    <inertial>
      <origin rpy="0 0 0" xyz="-0.023147 -0.0017078 -0.021581"/>
      <mass value="0.19752"/>
      <inertia ixx="6.4831E-05" ixy="8.4513E-06" ixz="1.4279E-05" iyy="0.00044684" iyz="-9.6663E-06" izz="0.00043202"/>
    </inertial>
    <visual>
      <origin rpy="0 0 0" xyz="0 0 0"/>
      <geometry>
        <mesh filename="package://blue_dexnet/meshes/primesense_link.STL"/>
      </geometry>
      <material name="">
        <color rgba="0.79216 0.81961 0.93333 1"/>
      </material>
    </visual>
    <collision>
      <origin rpy="0 0 0" xyz="0 0 0"/>
      <geometry>
        <mesh filename="package://blue_dexnet/meshes/primesense_link.STL"/>
      </geometry>
    </collision>
  </link>
  <joint name="primesense_joint" type="fixed">
    <!-- Pre-Brent's edits -->
    <!-- <origin -->
    <!-- xyz="0.011494 0.33383 0.61099" -->
    <!-- rpy="-1.5708 1.5708 -3.1416" /> -->
    <origin rpy="-1.5708 1.5708 -3.1416" xyz="0.116494 0.33383 0.72599"/>
    <parent link="camera_base_link"/>
    <child link="camera_link"/>
    <axis xyz="0 0 0"/>
  </joint>
  <link name="right_shoulder_roll_link">
    <inertial>
      <origin rpy="0 0 0" xyz="0.00526385736219506 2.70691865020822E-05 -0.0641638075944594"/>
      <mass value="1.91396434923"/>
      <inertia ixx="0.0057866591250737" ixy="3.71515699629511E-07" ixz="-6.32890111626103E-05" iyy="0.00530223654324281" iyz="8.9999884666805E-07" izz="0.00342399181200673"/>
    </inertial>
    <visual>
      <origin rpy="0 0 0" xyz="0 0 0"/>
      <geometry>
        <mesh filename="package://blue_descriptions/meshes/roll_link.STL"/>
      </geometry>
      <material name="">
        <color rgba="1 1 1 1"/>
      </material>
    </visual>
    <collision>
      <origin rpy="0 0 0" xyz="0 0 0"/>
      <geometry>
        <mesh filename="package://blue_descriptions/meshes/roll_link.STL"/>
      </geometry>
    </collision>
  </link>
  <joint name="right_shoulder_lift_joint" type="revolute">
    <origin rpy="-1.5708 4.4409E-16 3.1416" xyz="-0.01143 0 -0.18056"/>
    <parent link="right_shoulder_roll_link"/>
    <child link="right_shoulder_lift_link"/>
    <axis xyz="0 0 1"/>
    <limit effort="800" lower="-2.2944" upper="0" velocity="50"/>
  </joint>
  <link name="right_shoulder_accel_link"/>
  <joint name="right_shoulder_accel_joint" type="fixed">
    <origin rpy="1.5707963267949 0.328491802364426 5.16250107234938E-16" xyz="-0.020008330615085 -0.000510000000000066 -0.111067108096273"/>
    <parent link="right_shoulder_roll_link"/>
    <child link="right_shoulder_accel_link"/>
    <axis xyz="0 0 0"/>
  </joint>
  <link name="right_shoulder_lift_link">
    <inertial>
      <origin rpy="0 0 0" xyz="-5.0083559080677E-06 0.000232928456050885 -1.77451392545103E-05"/>
      <mass value="0.448307108622636"/>
      <inertia ixx="0.000804272985961788" ixy="4.84548777859872E-08" ixz="2.09160815704306E-06" iyy="0.000818260636171894" iyz="-1.44954778549764E-08" izz="0.000550840705045094"/>
    </inertial>
    <visual>
      <origin rpy="0 0 0" xyz="0 0 0"/>
      <geometry>
        <mesh filename="package://blue_descriptions/meshes/lift_link.STL"/>
      </geometry>
      <material name="">
        <color rgba="0.116747 0.862745 1.0 1"/>
      </material>
    </visual>
    <collision>
      <origin rpy="0 0 0" xyz="0 0 0"/>
      <geometry>
        <mesh filename="package://blue_descriptions/meshes/lift_link.STL"/>
      </geometry>
    </collision>
  </link>
  <joint name="right_shoulder_roll_joint" type="revolute">
    <origin rpy="-1.5708 -1.5673 -3.1416" xyz="0 0.070147 -6.25E-05"/>
    <parent link="right_shoulder_lift_link"/>
    <child link="right_elbow_roll_link"/>
    <axis xyz="0 0 1"/>
    <limit effort="800" lower="-2.6761" upper="2.6761" velocity="50"/>
  </joint>
  <link name="right_elbow_roll_link">
    <inertial>
      <origin rpy="0 0 0" xyz="0.00526385736219506 2.70691865020822E-05 -0.0641638075944594"/>
      <mass value="1.91396434923"/>
      <inertia ixx="0.0057866591250737" ixy="3.71515699629511E-07" ixz="-6.32890111626103E-05" iyy="0.00530223654324281" iyz="8.9999884666805E-07" izz="0.00342399181200673"/>
    </inertial>
    <visual>
      <origin rpy="0 0 0" xyz="0 0 0"/>
      <geometry>
        <mesh filename="package://blue_descriptions/meshes/roll_link.STL"/>
      </geometry>
      <material name="">
        <color rgba="1 1 1 1"/>
      </material>
    </visual>
    <collision>
      <origin rpy="0 0 0" xyz="0 0 0"/>
      <geometry>
        <mesh filename="package://blue_descriptions/meshes/roll_link.STL"/>
      </geometry>
    </collision>
  </link>
  <joint name="right_elbow_lift_joint" type="revolute">
    <origin rpy="-1.5708 4.4409E-16 3.1416" xyz="-0.01143 0 -0.18056"/>
    <parent link="right_elbow_roll_link"/>
    <child link="right_elbow_lift_link"/>
    <axis xyz="0 0 1"/>
    <limit effort="800" lower="-2.2944" upper="0" velocity="50"/>
  </joint>
  <link name="right_elbow_accel_link"/>
  <joint name="right_elbow_accel_joint" type="fixed">
    <origin rpy="1.5707963267949 0.328491802364426 5.16250107234938E-16" xyz="-0.020008330615085 -0.000510000000000066 -0.111067108096273"/>
    <parent link="right_elbow_roll_link"/>
    <child link="right_elbow_accel_link"/>
    <axis xyz="0 0 0"/>
  </joint>
  <link name="right_elbow_lift_link">
    <inertial>
      <origin rpy="0 0 0" xyz="-5.0083559080677E-06 0.000232928456050885 -1.77451392545103E-05"/>
      <mass value="0.448307108622636"/>
      <inertia ixx="0.000804272985961788" ixy="4.84548777859872E-08" ixz="2.09160815704306E-06" iyy="0.000818260636171894" iyz="-1.44954778549764E-08" izz="0.000550840705045094"/>
    </inertial>
    <visual>
      <origin rpy="0 0 0" xyz="0 0 0"/>
      <geometry>
        <mesh filename="package://blue_descriptions/meshes/lift_link.STL"/>
      </geometry>
      <material name="">
        <color rgba="0.116747 0.862745 1.0 1"/>
      </material>
    </visual>
    <collision>
      <origin rpy="0 0 0" xyz="0 0 0"/>
      <geometry>
        <mesh filename="package://blue_descriptions/meshes/lift_link.STL"/>
      </geometry>
    </collision>
  </link>
  <joint name="right_elbow_roll_joint" type="revolute">
    <origin rpy="-1.5708 1.5673 -3.1416" xyz="0 0.070147 -6.25E-05"/>
    <parent link="right_elbow_lift_link"/>
    <child link="right_wrist_roll_link"/>
    <axis xyz="0 0 1"/>
    <limit effort="800" lower="-2.6761" upper="2.6761" velocity="50"/>
  </joint>
  <link name="right_wrist_roll_link">
    <inertial>
      <origin rpy="0 0 0" xyz="0.00526385736219506 2.70691865020822E-05 -0.0641638075944594"/>
      <mass value="1.41368434923"/>
      <inertia ixx="0.0057866591250737" ixy="3.71515699629511E-07" ixz="-6.32890111626103E-05" iyy="0.00530223654324281" iyz="8.9999884666805E-07" izz="0.00342399181200673"/>
    </inertial>
    <visual>
      <origin rpy="0 0 0" xyz="0 0 0"/>
      <geometry>
        <mesh filename="package://blue_descriptions/meshes/roll_link.STL"/>
      </geometry>
      <material name="">
        <color rgba="1 1 1 1"/>
      </material>
    </visual>
    <collision>
      <origin rpy="0 0 0" xyz="0 0 0"/>
      <geometry>
        <mesh filename="package://blue_descriptions/meshes/roll_link.STL"/>
      </geometry>
    </collision>
  </link>
  <joint name="right_wrist_lift_joint" type="revolute">
    <origin rpy="-1.5708 4.4409E-16 3.1416" xyz="-0.01143 0 -0.18056"/>
    <parent link="right_wrist_roll_link"/>
    <child link="right_wrist_lift_link"/>
    <axis xyz="0 0 1"/>
    <limit effort="800" lower="-2.2944" upper="0" velocity="50"/>
  </joint>
  <link name="right_wrist_accel_link"/>
  <joint name="right_wrist_accel_joint" type="fixed">
    <origin rpy="1.5707963267949 0.328491802364426 5.16250107234938E-16" xyz="-0.020008330615085 -0.000510000000000066 -0.111067108096273"/>
    <parent link="right_wrist_roll_link"/>
    <child link="right_wrist_accel_link"/>
    <axis xyz="0 0 0"/>
  </joint>
  <link name="right_wrist_lift_link">
    <inertial>
      <origin rpy="0 0 0" xyz="-5.0083559080677E-06 0.000232928456050885 -1.77451392545103E-05"/>
      <mass value="0.448307108622636"/>
      <inertia ixx="0.000804272985961788" ixy="4.84548777859872E-08" ixz="2.09160815704306E-06" iyy="0.000818260636171894" iyz="-1.44954778549764E-08" izz="0.000550840705045094"/>
    </inertial>
    <visual>
      <origin rpy="0 0 0" xyz="0 0 0"/>
      <geometry>
        <mesh filename="package://blue_descriptions/meshes/lift_link.STL"/>
      </geometry>
      <material name="">
        <color rgba="0.116747 0.862745 1.0 1"/>
      </material>
    </visual>
    <collision>
      <origin rpy="0 0 0" xyz="0 0 0"/>
      <geometry>
        <mesh filename="package://blue_descriptions/meshes/lift_link.STL"/>
      </geometry>
    </collision>
  </link>
  <joint name="right_wrist_roll_joint" type="revolute">
    <origin rpy="-1.5708 0.0 -3.1416" xyz="0 0.070147 -6.25E-05"/>
    <parent link="right_wrist_lift_link"/>
    <child link="right_end_roll_link"/>
    <axis xyz="0 0 1"/>
    <limit effort="800" lower="-2.6761" upper="2.6761" velocity="50"/>
  </joint>
  <link name="right_end_roll_link">
    <inertial>
      <origin rpy="0 0 0" xyz="0.00526385736219506 2.70691865020822E-05 -0.0641638075944594"/>
      <mass value="0.657109755986862"/>
      <inertia ixx="0.0057866591250737" ixy="3.71515699629511E-07" ixz="-6.32890111626103E-05" iyy="0.00530223654324281" iyz="8.9999884666805E-07" izz="0.00342399181200673"/>
    </inertial>
    <visual>
      <origin rpy="0 0 0" xyz="0 0 0"/>
      <geometry>
        <mesh filename="package://blue_descriptions/meshes/wrist_roll_link.STL"/>
      </geometry>
      <material name="">
        <color rgba="1 1 1 1"/>
      </material>
    </visual>
    <collision>
      <origin rpy="0 0 0" xyz="0 0 0"/>
      <geometry>
        <mesh filename="package://blue_descriptions/meshes/wrist_roll_link.STL"/>
      </geometry>
    </collision>
  </link>
  <link name="right_gripper_link">
    <inertial>
      <origin rpy="0 0 0" xyz="-7.00549073506807E-05 2.51271935254316E-05 -0.052367118189184"/>
      <mass value="0.0047109755986862"/>
      <inertia ixx="0.000916887873826385" ixy="-6.04547948818479E-08" ixz="0.6796133363069E-06" iyy="0.000877268801166351" iyz="0.64172907801915E-07" izz="0.000293333065172452"/>
    </inertial>
  </link>
  <joint name="right_gripper_joint" type="revolute">
    <origin rpy="-1.5708 -2.4803E-15 -3.1416" xyz="0 0.070147 -6.25E-05"/>
    <parent link="right_end_roll_link"/>
    <child link="right_gripper_link"/>
    <axis xyz="0 0 1"/>
    <limit effort="800" lower="-2.6761" upper="2.6761" velocity="50"/>
  </joint>
  <link name="right_gripper_finger_link">
    </link>
  <joint name="right_gripper_finger_joint" type="fixed">
    <origin rpy="1.5708 1.5708 1.5708" xyz="0 0.0 -0.18"/>
    <parent link="right_end_roll_link"/>
    <child link="right_gripper_finger_link"/>
  </joint>
</robot>

